Workbook

Sheet Fleet_Data
A1: Vehicle_ID | B1: Driver_Name | C1: Date | D1: Distance_KM | E1: Fuel_Consumed_L | F1: Idle_Time_Hrs | G1: Trips | H1: Average_Speed_KMH | I1: Route_Compliance_Pct
A2: VH-004 | B2: Driver D | C2: 46026 | D2: 354.4 | E2: 102.4 | F2: 0.8 | G2: 2 | H2: 60.5 | I2: 98.4
A3: VH-003 | B3: Driver C | C3: 46098 | D3: 236.1 | E3: 82 | F3: 1.1 | G3: 1 | H3: 55.3 | I3: 95.7
A4: VH-018 | B4: Driver R | C4: 46076 | D4: 161.6 | E4: 36.8 | F4: 3.7 | G4: 1 | H4: 64.1 | I4: 87.4
A5: VH-014 | B5: Driver N | C5: 46066 | D5: 182.8 | E5: 54.1 | F5: 3.5 | G5: 2 | H5: 34.2 | I5: 86.5
A6: VH-012 | B6: Driver L | C6: 46100 | D6: 177.9 | E6: 61 | F6: 2.2 | G6: 2 | H6: 73.8 | I6: 90.7
A7: VH-018 | B7: Driver R | C7: 46060 | D7: 386.9 | E7: 86.6 | F7: 3.9 | G7: 4 | H7: 61.7 | I7: 85.7
A8: VH-008 | B8: Driver H | C8: 46060 | D8: 444.5 | E8: 87 | F8: 3.9 | G8: 7 | H8: 42.5 | I8: 94.5
A9: VH-012 | B9: Driver L | C9: 46043 | D9: 217 | E9: 64.5 | F9: 1.3 | G9: 2 | H9: 57.4 | I9: 87.6
A10: VH-008 | B10: Driver H | C10: 46043 | D10: 251 | E10: 71.1 | F10: 4.2 | G10: 4 | H10: 60.8 | I10: 97.6
A11: VH-002 | B11: Driver B | C11: 46052 | D11: 384.1 | E11: 77.2 | F11: 1.9 | G11: 2 | H11: 39.5 | I11: 99.1
A12: VH-011 | B12: Driver K | C12: 46050 | D12: 322.5 | E12: 83.4 | F12: 4.1 | G12: 8 | H12: 36.4 | I12: 87.1
A13: VH-018 | B13: Driver R | C13: 46091 | D13: 177.2 | E13: 40.5 | F13: 4.1 | G13: 7 | H13: 46.3 | I13: 100
... A805: VH-004 | B805: Driver D | C805: 46026 | D805: 220 | E805: 55 | F805: 2 | G805: 4 | H805: 50 | I805: 40

Sheet Fuel_Events
A1: Vehicle_ID | B1: Timestamp | C1: Event_Type | D1: Quantity_L | E1: Location | F1: HOUR
A2: VH-002 | B2: 46057.117 | C2: Consumption Alert | D2: 19.7 | E2: Vadodara | F2: =HOUR(B2) -> 2
A3: VH-013 | B3: 46091.723 | C3: Refuel | D3: 130.8 | E3: Ahmedabad | F3: =HOUR(B3) -> 17
A4: VH-005 | B4: 46066.723 | C4: Fuel Drop | D4: 14 | E4: Rajkot | F4: =HOUR(B4) -> 17
A5: VH-003 | B5: 46099.503 | C5: Fuel Fill | D5: 61 | E5: Rajkot | F5: =HOUR(B5) -> 12
A6: VH-004 | B6: 46028.113 | C6: Fuel Drop | D6: 11.9 | E6: Vadodara | F6: =HOUR(B6) -> 2
A7: VH-010 | B7: 46078.771 | C7: Refuel | D7: 81 | E7: Vadodara | F7: =HOUR(B7) -> 18
A8: VH-010 | B8: 46066.702 | C8: Consumption Alert | D8: 16.4 | E8: Bharuch | F8: =HOUR(B8) -> 16
A9: VH-017 | B9: 46095.417 | C9: Consumption Alert | D9: 54.1 | E9: Indore | F9: =HOUR(B9) -> 10
A10: VH-017 | B10: 46078.899 | C10: Consumption Alert | D10: 33.6 | E10: Rajkot | F10: =HOUR(B10) -> 21
A11: VH-012 | B11: 46088.079 | C11: Fuel Drop | D11: 44.9 | E11: Vadodara | F11: =HOUR(B11) -> 1
A12: VH-016 | B12: 46107.34 | C12: Refuel | D12: 63.8 | E12: Rajkot | F12: =HOUR(B12) -> 8
A13: VH-003 | B13: 46081.525 | C13: Refuel | D13: 22.1 | E13: Bharuch | F13: =HOUR(B13) -> 12
... A304: VH-007 | B304: 46086.132 | C304: Fuel Drop | D304: 44.3 | E304: Remote Route | F304: =HOUR(B304) -> 3

Sheet Task_1_Data_Validation
A3: Part A – Fleet_Data Validation
B6: Missing Values Table
A8: Column | B8: Missing | C8: Action
A9: Fuel_Consumed_L | B9: 5 | C9: Replaced with Mean
A10: Idle_Time_Hrs | B10: 5 | C10: Replaced with Mean
A11: Route_Compliance_Pct | B11: 5 | C11: Replaced with Mean
A13: NOTE :Only 5 missing values were found in each numerical column. Since the missing percentage was very low, the missing values were replaced using the column mean.
B16: Duplicate Table
A18: Check | B18: Result | C18: Action
A19: Duplicate Records | B19: 6 | C19: Removed
B21: Suspicious Records
A23: Vehicle_ID | B23: Issue Identified | C23: Reason
A24: VH-001 | B24: High Fuel Consumption | C24: Vehicle travelled 250 KM but consumed 120 L of fuel, resulting in very low fuel efficiency
A25: VH-002 | B25: High Idle Time | C25: Idle time is 12 hours and average speed is only 20 KM/H, indicating excessive engine idle time.
A26: VH-003 | B26: Unrealistic Fuel Efficiency | C26: Vehicle travelled 400 KM using only 15 L of fuel, which is unusually high efficiency.
A27: VH-004 | B27: Poor Route Compliance | C27: Route compliance is only 40%, indicating significant route deviation.
A31: Part B – Fuel_Events Validation
B34: Missing Values Table
A37: Column | B37: Missing Values | C37: Action Taken
A38: Vehicle_ID | B38: 0 | C38: No Action Required
A39: Timestamp | B39: 0 | C39: No Action Required
A40: Event_Type | B40: 0 | C40: No Action Required
A41: Quantity_L | B41: 0 | C41: No Action Required
A42: Location | B42: 0 | C42: No Action Required
A44: Note: No missing values were found in the Fuel_Events dataset.
B46: Duplicate Table
A48: Check | B48: Result | C48: Action Taken
A49: Duplicate Records | B49: 0 | C49: No Action Required
B51: Suspicious Records
A53: Potential Fuel Theft Cases (Remote Route Fuel Drops)
A55: Vehicle_ID | B55: Date & Time | C55: Fuel Drop (L) | D55: Location | E55: Risk
A56: VH-001 | B56: 46068.094 | C56: 48.5 | D56: Remote Route | E56: High
A57: VH-001 | B57: 46073.069 | C57: 52.1 | D57: Remote Route | E57: High
A58: VH-007 | B58: 46086.132 | C58: 44.3 | D58: Remote Route | E58: High
A60: Three remote-route fuel drops occurred between 1–3 AM with losses exceeding 40 L, indicating possible fuel theft or leakage.
A63: Fuel Drops During Unusual Hours (>30 L)
A65: Vehicle_ID | B65: Date & Time | C65: Qty (L) | D65: Location | E65: Remark
A66: VH-016 | B66: 46072.199 | C66: 56.8 | D66: Rajkot | E66: High fuel drop
A67: VH-014 | B67: 46078.985 | C67: 55.3 | D67: Ahmedabad | E67: Night-time fuel drop
A68: VH-005 | B68: 46107.158 | C68: 55.1 | D68: Vadodara | E68: High fuel drop
...

Sheet Task 2 – KPI Analysis
A1: TASK 2 – KPI ANALYSIS
A3: KPI | B3: ANS
A4: Total Distance Travelled | B4: =SUM(Fleet_Data!D2:D805) -> 212316
A5: Total Fuel Consumed | B5: =SUM(Fleet_Data!E2:E805) -> 52569.7
A6: Average Fuel Efficiency | B6: =ROUND(B4/B5,2) -> 4.04
A7: Average Idle Time | B7: =ROUND(AVERAGE(Fleet_Data!F2:F805),2) -> 2.36
A8: Avg Route Compliance | B8: =ROUND(AVERAGE(Fleet_Data!I2:I805),2) -> 92.54
A10: Top 5 Vehicles by Distance
A12: Vehicle_ID | B12: Sum of Distance_KM
A13: VH-018 | B13: 14685.8
A14: VH-011 | B14: 14013.8
A15: VH-003 | B15: 13386.5
A16: VH-020 | B16: 12803.5
A17: VH-005 | B17: 12650.3
A18: Grand Total | B18: 67539.9
A20: - Top 5 Vehicles by Fuel Consumption
A22: Vehicle_ID | B22: Sum of Fuel_Consumed_L
A23: VH-018 | B23: 3629.2
A24: VH-011 | B24: 3334.1
A25: VH-020 | B25: 3323.6
A26: VH-005 | B26: 3237.2
A27: VH-003 | B27: 3214.7
A28: Grand Total | B28: 16738.8

Sheet Task 3 – Business Insights 
A1: Task 3 – Business Insights
A7: Q1 | B7: 1. Least Fuel Efficient Vehicles (Bottom 5 by KM/L)
A9: Vehicle ID | B9: Sum of Distance_KM | C9: Sum of Fuel_Consumed_L | D9: Fuel Efficiency
A10: VH-009 | B10: 9519.5 | C10: 2563 | D10: =B10/C10 -> 3.7142021
A11: VH-001 | B11: 10172.9 | C11: 2661.6 | D11: =B11/C11 -> 3.8220995
A12: VH-020 | B12: 12803.5 | C12: 3323.6 | D12: =B12/C12 -> 3.8522987
A13: VH-005 | B13: 12650.3 | C13: 3237.2 | D13: =B13/C13 -> 3.9077907
A14: VH-012 | B14: 9376.8 | C14: 2376.4 | D14: =B14/C14 -> 3.9458004
A17: Q2 | B17: 2. Drivers with Unusually High Idle Times (Top 5 by Avg Idle)
A19: Driver | B19: Avg Idle (Hrs)
A20: Driver R | B20: 2.61
A21: Driver A | B21: 2.54
A22: Driver L | B22: 2.53
A23: Driver J | B23: 2.51
A24: Driver K | B24: 2.5
A27: Q3 | B27: 3. Which vehicles show abnormal fuel consumption?
A29: Vehicle ID | B29: Sum of Distance_KM | C29: Sum of Fuel_Consumed_L | D29: Fuel Efficiency
A30: VH-009 | B30: 9519.5 | C30: 2563 | D30: =B30/C30 -> 3.7142021
A31: VH-001 | B31: 10172.9 | C31: 2661.6 | D31: =B31/C31 -> 3.8220995
A32: VH-020 | B32: 12803.5 | C32: 3323.6 | D32: =B32/C32 -> 3.8522987
A33: VH-005 | B33: 12650.3 | C33: 3237.2 | D33: =B33/C33 -> 3.9077907
A35: VH-009, VH-001, VH-020, and VH-005 have unusually high fuel consumption due to lower fuel efficiency compared to other vehicles.
A40: Q4 | B40: 4. Vehicles with Poor Route Compliance (Lowest 5 Avg %)
A43: Vehicle ID | B43: Avg Compliance %
A44: VH-012 | B44: 90.01
A45: VH-001 | B45: 91.18
A46: VH-004 | B46: 91.34
A47: VH-019 | B47: 91.87
A48: VH-003 | B48: 92.03
A51: 5. Operational Improvement Recommendations
A52: Implement real-time idle-time alerts and driver scorecards; target average idle <2.0 hrs.
A53: Conduct route audits and geo-fence enforcement for vehicles with compliance <90%.
A54: Schedule efficiency diagnostics / maintenance for bottom-quartile fuel-efficiency vehicles.
A55: Cross-reference daily fuel events vs. reported consumption to detect variance early.
A56: Introduce mandatory post-trip fuel and idle data validation in the IoT pipeline.
A57: Train drivers on eco-driving and strict route adherence.

Sheet Task 4 – Fuel Investigation 
A1: TASK 4 – FUEL INVESTIGATION
A3: 1. Suspicious Fuel Drop Patterns – Summary
A4: Total Fuel Drop events | B4: =COUNTIF(Fuel_Events!C2:C304,"FUEL DROP") -> 96
A5: Fuel Drops >40 L | B5: =COUNTIFS(Fuel_Events!C2:C304,"FUEL DROP",Fuel_Events!D2:D304,">=40") -> 38
A6: Fuel Drops on Remote Route | B6: =COUNTIFS(Fuel_Events!C2:C304,"FUEL DROP",Fuel_Events!E2:E304,"REMOTE ROUTE") -> 3
A7: Fuel Drops at unusual hours (22:00–06:00): | B7: =COUNTIFS(Fuel_Events!C2:C304,"Fuel Drop",Fuel_Events!F2:F304,">=22")+COUNTIFS(Fuel_Events!C2:C304,"Fuel Drop",Fuel_Events!F2:F304,"<=6") -> 39
A9: 2. Fuel Drops during Unusual Hours (Hour <6 or >22) – Top by Quantity
A10: Vehicle_ID | B10: Timestamp | C10: Quantity_L | D10: Location | E10: Hour
A11: VH-016 | B11: 2026-02-19 04:47 | C11: 56.8 | D11: Rajkot | E11: 4
A12: VH-014 | B12: 2026-02-25 23:38 | C12: 55.3 | D12: Ahmedabad | E12: 23
A13: VH-005 | B13: 2026-03-26 03:47 | C13: 55.1 | D13: Vadodara | E13: 3
A14: VH-007 | B14: 2026-02-19 05:26 | C14: 53.2 | D14: Ahmedabad | E14: 5
A15: VH-001 | B15: 2026-02-20 01:40 | C15: 52.1 | D15: Remote Route | E15: 1
A16: VH-001 | B16: 2026-02-15 02:15 | C16: 48.5 | D16: Remote Route | E16: 2
A17: VH-019 | B17: 2026-02-06 05:12 | C17: 48.1 | D17: Rajkot | E17: 5
A18: VH-003 | B18: 2026-03-28 04:23 | C18: 45.9 | D18: Indore | E18: 4
A19: VH-012 | B19: 2026-03-07 01:54 | C19: 44.9 | D19: Vadodara | E19: 1
A20: VH-007 | B20: 2026-03-05 03:10 | C20: 44.3 | D20: Remote Route | E20: 3
A21: VH-005 | B21: 2026-02-04 05:31 | C21: 41.8 | D21: Indore | E21: 5
A22: VH-018 | B22: 2026-03-09 01:38 | C22: 41 | D22: Rajkot | E22: 1
... A25: VH-013 | B25: 2026-03-01 01:00 | C25: 30.1 | D25: Vadodara | E25: 1
A28: 3. Vehicles with Repeated Fuel-Drop Incidents
A29: Vehicle_ID | B29: Drop_Count
A30: VH-006 | B30: 9
A31: VH-012 | B31: 9
A32: VH-005 | B32: 9
A33: VH-007 | B33: 8
A34: VH-001 | B34: 7
A35: VH-018 | B35: 6
A36: VH-014 | B36: 6
A37: VH-020 | B37: 6
A38: VH-019 | B38: 5
A39: VH-017 | B39: 4
A42: 4. Potential Fuel Theft / Leakage Cases (Large drops + Remote or deep night)
A44: Vehicle_ID | B44: Timestamp | C44: Quantity_L | D44: Location | E44: Hour
A45: VH-016 | B45: 46072.199 | C45: 56.8 | D45: Rajkot | E45: 4
A46: VH-005 | B46: 46107.158 | C46: 55.1 | D46: Vadodara | E46: 3
A47: VH-001 | B47: 46073.069 | C47: 52.1 | D47: Remote Route | E47: 1
A48: VH-001 | B48: 46068.094 | C48: 48.5 | D48: Remote Route | E48: 2
A49: VH-003 | B49: 46109.183 | C49: 45.9 | D49: Indore | E49: 4
...
